<?xml version="1.0" encoding="utf-8"?>
<!-- =================================================================================== -->
<!-- |    This document was autogenerated by xacro from hand.urdf.xacro                | -->
<!-- |    EDITING THIS FILE BY HAND IS NOT RECOMMENDED                                 | -->
<!-- =================================================================================== -->
<robot name="hand">
  <link name="panda_hand">
    <visual>
      <geometry>
        <mesh filename="meshes/visual/hand.stl"/>
      </geometry>
    </visual>
    <collision>
      <origin rpy="0 1.57079632679 1.57079632679" xyz="0 0 0.04"/>
      <geometry>
        <cylinder length="0.1" radius="0.07"/>
      </geometry>
    </collision>
    <collision>
      <origin rpy="0 0 0" xyz="0 -0.05 0.04"/>
      <geometry>
        <sphere radius="0.07"/>
      </geometry>
    </collision>
    <collision>
      <origin rpy="0 0 0" xyz="0 0.05 0.04"/>
      <geometry>
        <sphere radius="0.07"/>
      </geometry>
    </collision>
    <!-- <collision>
        <origin xyz="0 0 0.1" rpy="0 ${pi/2} ${pi/2}"/>
        <geometry>
          <cylinder radius="${0.02+safety_distance}" length="0.1" />
        </geometry>
      </collision>
      <collision>
        <origin xyz="0 -0.05 0.1" rpy="0 0 0"/>
        <geometry>
          <sphere radius="${0.02+safety_distance}"  />
        </geometry>
      </collision>
      <collision>
        <origin xyz="0 0.05 0.1" rpy="0 0 0"/>
        <geometry>
          <sphere radius="${0.02+safety_distance}"  />
        </geometry>
      </collision> -->
  </link>
  <link name="panda_leftfinger">
    <visual>
      <geometry>
        <mesh filename="meshes/visual/finger.stl"/>
      </geometry>
    </visual>
  </link>
  <link name="panda_rightfinger">
    <visual>
      <origin rpy="0 0 3.14159265359" xyz="0 0 0"/>
      <geometry>
        <mesh filename="meshes/visual/finger.stl"/>
      </geometry>
    </visual>
  </link>
  <link name="panda_tcp">
  </link>
  <joint name="panda_tcp_joint" type="fixed">
    <parent link="panda_hand"/>
    <child link="panda_tcp"/>
    <origin rpy="0 0 0" xyz="0 0 0.105"/>
    <axis xyz="0 -1 0"/>
  </joint>
  <joint name="panda_finger_joint1" type="prismatic">
    <parent link="panda_hand"/>
    <child link="panda_leftfinger"/>
    <origin rpy="0 0 0" xyz="0 0 0.0584"/>
    <axis xyz="0 1 0"/>
    <limit effort="20" lower="0.0" upper="0.04" velocity="0.2"/>
  </joint>
  <joint name="panda_finger_joint2" type="prismatic">
    <parent link="panda_hand"/>
    <child link="panda_rightfinger"/>
    <origin rpy="0 0 0" xyz="0 0 0.0584"/>
    <axis xyz="0 -1 0"/>
    <limit effort="20" lower="0.0" upper="0.04" velocity="0.2"/>
    <mimic joint="panda_finger_joint1"/>
  </joint>
</robot>
